Workbook

Sheet Gantt
A1: Diagramme de Gantt du PFE — Overlyne | F1: Début du stage | G1: 46139 | I1: Légende | L1: Terminé | P1: En cours | T1: Prévu | X1: Phase | AB1: ◆ Jalon
A2: Système d'Intelligence Décisionnelle pour ERP | F2: Fin du stage | G2: 46322 | I2: Dates en bleu : modifiables. Trait rouge : semaine de la date de mise à jour (G3).
A3: Stage de fin d'études · Mahmoud Ben Hammouda · 27/04/2026 – 27/10/2026 | F3: Date de mise à jour | G3: 46293
I4: avr. 26 | J4: mai 26 | N4: juin 26 | S4: juil. 26 | W4: août 26 | AB4: sept. 26 | AF4: oct. 26
A5: N° | B5: Phase / tâche | C5: Début | D5: Fin | E5: Durée (j) | F5: Avancement | G5: Statut | H5: Type | I5: 46139 | J5: 46146 | K5: 46153 | L5: 46160 | M5: 46167 | N5: 46174 | O5: 46181 | P5: 46188 | Q5: 46195 | R5: 46202 | S5: 46209 | T5: 46216 | U5: 46223 | V5: 46230 | W5: 46237 | X5: 46244 | Y5: 46251 | Z5: 46258 | AA5: 46265 | AB5: 46272 | AC5: 46279 | AD5: 46286 | AE5: 46293 | AF5: 46300 | AG5: 46307 | AH5: 46314 | AI5: 46321
A6: 1 | B6: Cadrage, étude du métier et spécifications | C6: =MIN(C7:C11) -> 46139 | D6: =MAX(D7:D11) -> 46176 | E6: =D6-C6+1 -> 38 | F6: =MAX(0,MIN(1,($G$3-C6+1)/(D6-C6+1))) -> 1 | G6: =IF(D6<=$G$3,"Terminé",IF(C6>$G$3,"Prévu","En cours")) -> Terminé | H6: Phase
A7: 1.1 | B7: Immersion dans l'entreprise et étude de l'ERP | C7: 46139 | D7: 46152 | E7: =D7-C7+1 -> 14 | F7: =MAX(0,MIN(1,($G$3-C7+1)/(D7-C7+1))) -> 1 | G7: =IF(D7<=$G$3,"Terminé",IF(C7>$G$3,"Prévu","En cours")) -> Terminé | H7: Tâche
A8: 1.2 | B8: État de l'art : Decision Intelligence, multi-agents, XAI | C8: 46146 | D8: 46166 | E8: =D8-C8+1 -> 21 | F8: =MAX(0,MIN(1,($G$3-C8+1)/(D8-C8+1))) -> 1 | G8: =IF(D8<=$G$3,"Terminé",IF(C8>$G$3,"Prévu","En cours")) -> Terminé | H8: Tâche
A9: 1.3 | B9: Cahier des charges, PRD et étude de marché | C9: 46160 | D9: 46176 | E9: =D9-C9+1 -> 17 | F9: =MAX(0,MIN(1,($G$3-C9+1)/(D9-C9+1))) -> 1 | G9: =IF(D9<=$G$3,"Terminé",IF(C9>$G$3,"Prévu","En cours")) -> Terminé | H9: Tâche
A10: 1.4 | B10: Dictionnaire des données de l'ERP | C10: 46167 | D10: 46175 | E10: =D10-C10+1 -> 9 | F10: =MAX(0,MIN(1,($G$3-C10+1)/(D10-C10+1))) -> 1 | G10: =IF(D10<=$G$3,"Terminé",IF(C10>$G$3,"Prévu","En cours")) -> Terminé | H10: Tâche
A11: J1 | B11: Premier dépôt du projet (git) | C11: 46176 | D11: 46176 | E11: =D11-C11+1 -> 1 | F11: =MAX(0,MIN(1,($G$3-C11+1)/(D11-C11+1))) -> 1 | G11: =IF(D11<=$G$3,"Terminé",IF(C11>$G$3,"Prévu","En cours")) -> Terminé | H11: Jalon | I11: =IF(AND(I$5<=$C11,I$5+6>=$C11),"◆","") | J11: =IF(AND(J$5<=$C11,J$5+6>=$C11),"◆","") | K11: =IF(AND(K$5<=$C11,K$5+6>=$C11),"◆","") | L11: =IF(AND(L$5<=$C11,L$5+6>=$C11),"◆","") | M11: =IF(AND(M$5<=$C11,M$5+6>=$C11),"◆","") | N11: =IF(AND(N$5<=$C11,N$5+6>=$C11),"◆","") -> ◆ | O11: =IF(AND(O$5<=$C11,O$5+6>=$C11),"◆","") | P11: =IF(AND(P$5<=$C11,P$5+6>=$C11),"◆","") | ... AI11: =IF(AND(AI$5<=$C11,AI$5+6>=$C11),"◆","")
A12: 2 | B12: Données et Data Warehouse | C12: =MIN(C13:C15) -> 46169 | D12: =MAX(D13:D15) -> 46199 | E12: =D12-C12+1 -> 31 | F12: =MAX(0,MIN(1,($G$3-C12+1)/(D12-C12+1))) -> 1 | G12: =IF(D12<=$G$3,"Terminé",IF(C12>$G$3,"Prévu","En cours")) -> Terminé | H12: Phase
A13: 2.1 | B13: Intégration et préparation des données | C13: 46169 | D13: 46185 | E13: =D13-C13+1 -> 17 | F13: =MAX(0,MIN(1,($G$3-C13+1)/(D13-C13+1))) -> 1 | G13: =IF(D13<=$G$3,"Terminé",IF(C13>$G$3,"Prévu","En cours")) -> Terminé | H13: Tâche
A14: 2.2 | B14: Conception du Data Warehouse financier | C14: 46174 | D14: 46180 | E14: =D14-C14+1 -> 7 | F14: =MAX(0,MIN(1,($G$3-C14+1)/(D14-C14+1))) -> 1 | G14: =IF(D14<=$G$3,"Terminé",IF(C14>$G$3,"Prévu","En cours")) -> Terminé | H14: Tâche
A15: 2.3 | B15: Indicateurs clés (KPI) et formules | C15: 46181 | D15: 46199 | E15: =D15-C15+1 -> 19 | F15: =MAX(0,MIN(1,($G$3-C15+1)/(D15-C15+1))) -> 1 | G15: =IF(D15<=$G$3,"Terminé",IF(C15>$G$3,"Prévu","En cours")) -> Terminé | H15: Tâche
A16: 3 | B16: Machine learning et science des données | C16: =MIN(C17:C23) -> 46176 | D16: =MAX(D17:D23) -> 46292 | E16: =D16-C16+1 -> 117 | F16: =MAX(0,MIN(1,($G$3-C16+1)/(D16-C16+1))) -> 1 | G16: =IF(D16<=$G$3,"Terminé",IF(C16>$G$3,"Prévu","En cours")) -> Terminé | H16: Phase
A17: 3.1 | B17: Premiers modèles et pipeline de modélisation | C17: 46176 | D17: 46185 | E17: =D17-C17+1 -> 10 | F17: =MAX(0,MIN(1,($G$3-C17+1)/(D17-C17+1))) -> 1 | G17: =IF(D17<=$G$3,"Terminé",IF(C17>$G$3,"Prévu","En cours")) -> Terminé | H17: Tâche
A18: 3.2 | B18: Modèles prédictifs clients et ventes | C18: 46188 | D18: 46227 | E18: =D18-C18+1 -> 40 | F18: =MAX(0,MIN(1,($G$3-C18+1)/(D18-C18+1))) -> 1 | G18: =IF(D18<=$G$3,"Terminé",IF(C18>$G$3,"Prévu","En cours")) -> Terminé | H18: Tâche
A19: 3.3 | B19: Prévision de la demande et de l'approvisionnement | C19: 46209 | D19: 46232 | E19: =D19-C19+1 -> 24 | F19: =MAX(0,MIN(1,($G$3-C19+1)/(D19-C19+1))) -> 1 | G19: =IF(D19<=$G$3,"Terminé",IF(C19>$G$3,"Prévu","En cours")) -> Terminé | H19: Tâche
A20: 3.4 | B20: Refonte data science : évaluation hors période (CRISP-DM) | C20: 46266 | D20: 46281 | E20: =D20-C20+1 -> 16 | F20: =MAX(0,MIN(1,($G$3-C20+1)/(D20-C20+1))) -> 1 | G20: =IF(D20<=$G$3,"Terminé",IF(C20>$G$3,"Prévu","En cours")) -> Terminé | H20: Tâche
A21: 3.5 | B21: Registre des modèles et passerelle agents ↔ modèles | C21: 46272 | D21: 46283 | E21: =D21-C21+1 -> 12 | F21: =MAX(0,MIN(1,($G$3-C21+1)/(D21-C21+1))) -> 1 | G21: =IF(D21<=$G$3,"Terminé",IF(C21>$G$3,"Prévu","En cours")) -> Terminé | H21: Tâche
A22: 3.6 | B22: Deep learning : recommandation Wide & Deep (PyTorch) | C22: 46273 | D22: 46284 | E22: =D22-C22+1 -> 12 | F22: =MAX(0,MIN(1,($G$3-C22+1)/(D22-C22+1))) -> 1 | G22: =IF(D22<=$G$3,"Terminé",IF(C22>$G$3,"Prévu","En cours")) -> Terminé | H22: Tâche
A23: 3.7 | B23: Demande par référence (CRISP-DM, 31 méthodes) et diagnostic | C23: 46283 | D23: 46292 | E23: =D23-C23+1 -> 10 | F23: =MAX(0,MIN(1,($G$3-C23+1)/(D23-C23+1))) -> 1 | G23: =IF(D23<=$G$3,"Terminé",IF(C23>$G$3,"Prévu","En cours")) -> Terminé | H23: Tâche
A24: 4 | B24: Agents IA et explicabilité | C24: =MIN(C25:C30) -> 46181 | D24: =MAX(D25:D30) -> 46287 | E24: =D24-C24+1 -> 107 | F24: =MAX(0,MIN(1,($G$3-C24+1)/(D24-C24+1))) -> 1 | G24: =IF(D24<=$G$3,"Terminé",IF(C24>$G$3,"Prévu","En cours")) -> Terminé | H24: Phase
A25: 4.1 | B25: Premier graphe d'agents LangGraph | C25: 46181 | D25: 46185 | E25: =D25-C25+1 -> 5 | F25: =MAX(0,MIN(1,($G$3-C25+1)/(D25-C25+1))) -> 1 | G25: =IF(D25<=$G$3,"Terminé",IF(C25>$G$3,"Prévu","En cours")) -> Terminé | H25: Tâche
A26: 4.2 | B26: Flotte multi-agents d'aide à la décision | C26: 46202 | D26: 46232 | E26: =D26-C26+1 -> 31 | F26: =MAX(0,MIN(1,($G$3-C26+1)/(D26-C26+1))) -> 1 | G26: =IF(D26<=$G$3,"Terminé",IF(C26>$G$3,"Prévu","En cours")) -> Terminé | H26: Tâche
A27: 4.3 | B27: Copilote FinBot et pipeline RAG | C27: 46209 | D27: 46232 | E27: =D27-C27+1 -> 24 | F27: =MAX(0,MIN(1,($G$3-C27+1)/(D27-C27+1))) -> 1 | G27: =IF(D27<=$G$3,"Terminé",IF(C27>$G$3,"Prévu","En cours")) -> Terminé | H27: Tâche
A28: 4.4 | B28: Veille des appels d'offres (prototype) | C28: 46216 | D28: 46232 | E28: =D28-C28+1 -> 17 | F28: =MAX(0,MIN(1,($G$3-C28+1)/(D28-C28+1))) -> 1 | G28: =IF(D28<=$G$3,"Terminé",IF(C28>$G$3,"Prévu","En cours")) -> Terminé | H28: Tâche
A29: 4.5 | B29: Module d'IA explicable (XAI) | C29: 46266 | D29: 46280 | E29: =D29-C29+1 -> 15 | F29: =MAX(0,MIN(1,($G$3-C29+1)/(D29-C29+1))) -> 1 | G29: =IF(D29<=$G$3,"Terminé",IF(C29>$G$3,"Prévu","En cours")) -> Terminé | H29: Tâche
A30: 4.6 | B30: Restructuration de la flotte : 5 agents et volet fiabilité | C30: 46282 | D30: 46287 | E30: =D30-C30+1 -> 6 | F30: =MAX(0,MIN(1,($G$3-C30+1)/(D30-C30+1))) -> 1 | G30: =IF(D30<=$G$3,"Terminé",IF(C30>$G$3,"Prévu","En cours")) -> Terminé | H30: Tâche
A31: 5 | B31: Plateforme web et sécurité | C31: =MIN(C32:C39) -> 46188 | D31: =MAX(D32:D39) -> 46277 | E31: =D31-C31+1 -> 90 | F31: =MAX(0,MIN(1,($G$3-C31+1)/(D31-C31+1))) -> 1 | G31: =IF(D31<=$G$3,"Terminé",IF(C31>$G$3,"Prévu","En cours")) -> Terminé | H31: Phase
A32: 5.1 | B32: Tableau de bord décisionnel (Next.js / React) | C32: 46188 | D32: 46232 | E32: =D32-C32+1 -> 45 | F32: =MAX(0,MIN(1,($G$3-C32+1)/(D32-C32+1))) -> 1 | G32: =IF(D32<=$G$3,"Terminé",IF(C32>$G$3,"Prévu","En cours")) -> Terminé | H32: Tâche
A33: 5.2 | B33: API FastAPI, authentification, rôles et isolation | C33: 46223 | D33: 46265 | E33: =D33-C33+1 -> 43 | F33: =MAX(0,MIN(1,($G$3-C33+1)/(D33-C33+1))) -> 1 | G33: =IF(D33<=$G$3,"Terminé",IF(C33>$G$3,"Prévu","En cours")) -> Terminé | H33: Tâche
A34: 5.3 | B34: Avatar 3D de l'assistant (Three.js) | C34: 46244 | D34: 46258 | E34: =D34-C34+1 -> 15 | F34: =MAX(0,MIN(1,($G$3-C34+1)/(D34-C34+1))) -> 1 | G34: =IF(D34<=$G$3,"Terminé",IF(C34>$G$3,"Prévu","En cours")) -> Terminé | H34: Tâche
A35: 5.4 | B35: Simulation de scénarios d'encaissement (et si… ?) | C35: 46258 | D35: 46269 | E35: =D35-C35+1 -> 12 | F35: =MAX(0,MIN(1,($G$3-C35+1)/(D35-C35+1))) -> 1 | G35: =IF(D35<=$G$3,"Terminé",IF(C35>$G$3,"Prévu","En cours")) -> Terminé | H35: Tâche
A36: 5.5 | B36: Boucle d'action : tâches, actions clients, mesure d'impact | C36: 46266 | D36: 46277 | E36: =D36-C36+1 -> 12 | F36: =MAX(0,MIN(1,($G$3-C36+1)/(D36-C36+1))) -> 1 | G36: =IF(D36<=$G$3,"Terminé",IF(C36>$G$3,"Prévu","En cours")) -> Terminé | H36: Tâche
A37: 5.6 | B37: Portail d'administration et espace client | C37: 46251 | D37: 46270 | E37: =D37-C37+1 -> 20 | F37: =MAX(0,MIN(1,($G$3-C37+1)/(D37-C37+1))) -> 1 | G37: =IF(D37<=$G$3,"Terminé",IF(C37>$G$3,"Prévu","En cours")) -> Terminé | H37: Tâche
A38: 5.7 | B38: Conteneurisation Docker, PostgreSQL et intégration continue | C38: 46230 | D38: 46277 | E38: =D38-C38+1 -> 48 | F38: =MAX(0,MIN(1,($G$3-C38+1)/(D38-C38+1))) -> 1 | G38: =IF(D38<=$G$3,"Terminé",IF(C38>$G$3,"Prévu","En cours")) -> Terminé | H38: Tâche
A39: J2 | B39: Plateforme intégrée (agents, RAG, tableau de bord) | C39: 46232 | D39: 46232 | E39: =D39-C39+1 -> 1 | F39: =MAX(0,MIN(1,($G$3-C39+1)/(D39-C39+1))) -> 1 | G39: =IF(D39<=$G$3,"Terminé",IF(C39>$G$3,"Prévu","En cours")) -> Terminé | H39: Jalon | I39: =IF(AND(I$5<=$C39,I$5+6>=$C39),"◆","") | J39: =IF(AND(J$5<=$C39,J$5+6>=$C39),"◆","") | K39: =IF(AND(K$5<=$C39,K$5+6>=$C39),"◆","") | L39: =IF(AND(L$5<=$C39,L$5+6>=$C39),"◆","") | M39: =IF(AND(M$5<=$C39,M$5+6>=$C39),"◆","") | N39: =IF(AND(N$5<=$C39,N$5+6>=$C39),"◆","") | O39: =IF(AND(O$5<=$C39,O$5+6>=$C39),"◆","") | P39: =IF(AND(P$5<=$C39,P$5+6>=$C39),"◆","") | ... AI39: =IF(AND(AI$5<=$C39,AI$5+6>=$C39),"◆","")
A40: 6 | B40: Lecture automatique des factures (OCR) | C40: =MIN(C41:C43) -> 46266 | D40: =MAX(D41:D43) -> 46286 | E40: =D40-C40+1 -> 21 | F40: =MAX(0,MIN(1,($G$3-C40+1)/(D40-C40+1))) -> 1 | G40: =IF(D40<=$G$3,"Terminé",IF(C40>$G$3,"Prévu","En cours")) -> Terminé | H40: Phase
...

Sheet Détail des tâches
A1: Détail des tâches réalisées et prévues
A3: N° | B3: Tâche | C3: Début | D3: Fin | E3: Statut | F3: Description | G3: Livrables / preuves
A4: 1 | B4: Cadrage, étude du métier et spécifications
A5: 1.1 | B5: Immersion dans l'entreprise et étude de l'ERP | C5: =Gantt!C7 -> 46139 | D5: =Gantt!D7 -> 46152 | E5: =Gantt!G7 -> Terminé | F5: Découverte de l'activité (distribution de réactifs de laboratoire), des processus ventes, achats et stocks, et des exports de l'ERP. | G5: Notes de cadrage
A6: 1.2 | B6: État de l'art : Decision Intelligence, multi-agents, XAI | C6: =Gantt!C8 -> 46146 | D6: =Gantt!D8 -> 46166 | E6: =Gantt!G8 -> Terminé | F6: Étude des plateformes d'aide à la décision, des architectures multi-agents (LangGraph, LangChain), de l'IA explicable (SHAP) et du RAG. | G6: Synthèse bibliographique
A7: 1.3 | B7: Cahier des charges, PRD et étude de marché | C7: =Gantt!C9 -> 46160 | D7: =Gantt!D9 -> 46176 | E7: =Gantt!G9 -> Terminé | F7: Rédaction du besoin, du PRD, du product brief et de l'étude de marché (méthode BMAD). Premier dépôt git le 03/06. | G7: PRD, product brief (_bmad-output)
A8: 1.4 | B8: Dictionnaire des données de l'ERP | C8: =Gantt!C10 -> 46167 | D8: =Gantt!D10 -> 46175 | E8: =Gantt!G10 -> Terminé | F8: Description de chaque table et colonne exportée : sens métier, type, qualité, colonnes vides (dates de paiement absentes). | G8: data_pfe_data_dictionary.xlsx (02/06)
A9: J1 | B9: Premier dépôt du projet (git) | C9: =Gantt!C11 -> 46176 | D9: =Gantt!D11 -> 46176 | E9: =Gantt!G11 -> Terminé | F9: Initialisation du dépôt. | G9: Commit initial
A10: 2 | B10: Données et Data Warehouse
A11: 2.1 | B11: Intégration et préparation des données | C11: =Gantt!C13 -> 46169 | D11: =Gantt!D13 -> 46185 | E11: =Gantt!G13 -> Terminé | F11: Import des CSV de l'ERP, nettoyage, typage, contrôle d'intégrité du chiffre d'affaires, des avoirs et des doublons. | G11: run_data_preparation.py, ml_engine/preprocessing
A12: 2.2 | B12: Conception du Data Warehouse financier | C12: =Gantt!C14 -> 46174 | D12: =Gantt!D14 -> 46180 | E12: =Gantt!G14 -> Terminé | F12: Modèle en étoile (faits et dimensions) dans DuckDB : ventes, achats, stocks, devis, clients. | G12: Schéma dw_beautiful.png, draw_dw.py (07/06)
A13: 2.3 | B13: Indicateurs clés (KPI) et formules | C13: =Gantt!C15 -> 46181 | D13: =Gantt!D15 -> 46199 | E13: =Gantt!G15 -> Terminé | F13: Définition et calcul des KPI (chiffre d'affaires, marge, DSO, encours, rotation des stocks), fidèles au code. | G13: docs/KPI_FORMULES.md
A14: 3 | B14: Machine learning et science des données
A15: 3.1 | B15: Premiers modèles et pipeline de modélisation | C15: =Gantt!C17 -> 46176 | D15: =Gantt!D17 -> 46185 | E15: =Gantt!G17 -> Terminé | F15: Pipeline de préparation et de modélisation par phases, premiers modèles de base. | G15: ml_modeling.py (07/06), ml_engine/phases (12/06)
A16: 3.2 | B16: Modèles prédictifs clients et ventes | C16: =Gantt!C18 -> 46188 | D16: =Gantt!D18 -> 46227 | E16: =Gantt!G18 -> Terminé | F16: Décrochage client, segmentation, conversion des devis, érosion de marge, conditions de crédit. | G16: ml_engine/analytics, ml_engine/models
A17: 3.3 | B17: Prévision de la demande et de l'approvisionnement | C17: =Gantt!C19 -> 46209 | D17: =Gantt!D19 -> 46232 | E17: =Gantt!G19 -> Terminé | F17: Prévision mensuelle de la demande et analyse de l'approvisionnement. | G17: ml_engine/forecasting (commit du 29/07)
A18: 3.4 | B18: Refonte data science : évaluation hors période (CRISP-DM) | C18: =Gantt!C20 -> 46266 | D18: =Gantt!D20 -> 46281 | E18: =Gantt!G20 -> Terminé | F18: Réévaluation de tous les modèles sur des mois postérieurs à l'entraînement, comparaison à une règle simple, accuracy et balanced accuracy. | G18: reports/METRICS_REPORT.md
A19: 3.5 | B19: Registre des modèles et passerelle agents ↔ modèles | C19: =Gantt!C21 -> 46272 | D19: =Gantt!D21 -> 46283 | E19: =Gantt!G21 -> Terminé | F19: Registre qui décide si un modèle est servi, refusé ou retiré ; passerelle unique entre les agents et les modèles. | G19: ml_engine/registre.py, ml_engine/passerelle.py
A20: 3.6 | B20: Deep learning : recommandation Wide & Deep (PyTorch) | C20: =Gantt!C22 -> 46273 | D20: =Gantt!D22 -> 46284 | E20: =Gantt!G22 -> Terminé | F20: Réseau Wide & Deep comparé à LightGBM sur la recommandation de produits (NDCG@10). | G20: ml_engine/deep, docs/DEEP_LEARNING.md
A21: 3.7 | B21: Demande par référence (CRISP-DM, 31 méthodes) et diagnostic | C21: =Gantt!C23 -> 46283 | D21: =Gantt!D23 -> 46292 | E21: =Gantt!G23 -> Terminé | F21: Prévision par référence de réactif : règles, Croston/TSB, ETS, LightGBM, XGBoost, CatBoost, N-HiTS, DeepAR ; médiane 12 mois retenue ; diagnostic de l'écart validation/test. | G21: docs/CRISP_DM_DEMANDE_REFERENCE.md, evaluation_demande
A22: 4 | B22: Agents IA et explicabilité
A23: 4.1 | B23: Premier graphe d'agents LangGraph | C23: =Gantt!C25 -> 46181 | D23: =Gantt!D25 -> 46185 | E23: =Gantt!G25 -> Terminé | F23: Superviseur, routeur, agent SQL et agent de rapport sur l'entrepôt. | G23: graphs/, agents/ (commit du 12/06)
A24: 4.2 | B24: Flotte multi-agents d'aide à la décision | C24: =Gantt!C26 -> 46202 | D24: =Gantt!D26 -> 46232 | E24: =Gantt!G26 -> Terminé | F24: Agents spécialisés en parallèle, arbitre qui classe les priorités, rédacteur du briefing de direction. | G24: agents/fleet (commit du 29/07)
A25: 4.3 | B25: Copilote FinBot et pipeline RAG | C25: =Gantt!C27 -> 46209 | D25: =Gantt!D27 -> 46232 | E25: =Gantt!G27 -> Terminé | F25: Assistant conversationnel sur les indicateurs réels et une base documentaire indexée (embeddings, FAISS, LangChain). | G25: rag/, Copilot.tsx
A26: 4.4 | B26: Veille des appels d'offres (prototype) | C26: =Gantt!C28 -> 46216 | D26: =Gantt!D28 -> 46232 | E26: =Gantt!G28 -> Terminé | F26: Collecte automatisée d'appels d'offres publics pour l'agent commercial. | G26: Commit du 29/07
A27: 4.5 | B27: Module d'IA explicable (XAI) | C27: =Gantt!C29 -> 46266 | D27: =Gantt!D29 -> 46280 | E27: =Gantt!G29 -> Terminé | F27: Bouton « Pourquoi ? » : décomposition exacte des contributions et valeurs SHAP pour chaque client, devis et produit. | G27: docs/XAI.md, Pourquoi.tsx
A28: 4.6 | B28: Restructuration de la flotte : 5 agents et volet fiabilité | C28: =Gantt!C30 -> 46282 | D28: =Gantt!D30 -> 46287 | E28: =Gantt!G30 -> Terminé | F28: Fusion en cinq agents (Commercial, Risque client, Recouvrement, Trésorerie, Stock & Approvisionnement) et surveillance de la fiabilité des modèles. | G28: docs/ARCHITECTURE_AGENTS.md
A29: 5 | B29: Plateforme web et sécurité
A30: 5.1 | B30: Tableau de bord décisionnel (Next.js / React) | C30: =Gantt!C32 -> 46188 | D30: =Gantt!D32 -> 46232 | E30: =Gantt!G32 -> Terminé | F30: Interface : KPI, panneaux risque client, commercial, stock et prévisions, briefing des agents. | G30: frontend/ (commit du 29/07)
A31: 5.2 | B31: API FastAPI, authentification, rôles et isolation | C31: =Gantt!C33 -> 46223 | D31: =Gantt!D33 -> 46265 | E31: =Gantt!G33 -> Terminé | F31: Comptes direction, employé et client ; bcrypt, JWT, limitation des tentatives ; isolation des données de chaque client côté serveur. | G31: api/auth, docs/SECURITY.md
A32: 5.3 | B32: Avatar 3D de l'assistant (Three.js) | C32: =Gantt!C34 -> 46244 | D32: =Gantt!D34 -> 46258 | E32: =Gantt!G34 -> Terminé | F32: Avatar animé (visèmes, émotions) avec solutions de repli. | G32: FinBotAvatar3D.tsx, docs/AVATAR_3D.md
A33: 5.4 | B33: Simulation de scénarios d'encaissement (et si… ?) | C33: =Gantt!C35 -> 46258 | D33: =Gantt!D35 -> 46269 | E33: =Gantt!G35 -> Terminé | F33: Effet de retards de paiement par secteur sur l'encaissement et la trésorerie, hypothèses visibles et modifiables. | G33: ml_engine/analytics/payment_scenario.py
A34: 5.5 | B34: Boucle d'action : tâches, actions clients, mesure d'impact | C34: =Gantt!C36 -> 46266 | D34: =Gantt!D36 -> 46277 | E34: =Gantt!G36 -> Terminé | F34: Une alerte devient une tâche confiée ou une action du client ; le résultat est mesuré et renvoyé vers les modèles. | G34: docs/BOUCLE_ACTION.md, TachesPanel.tsx
A35: 5.6 | B35: Portail d'administration et espace client | C35: =Gantt!C37 -> 46251 | D35: =Gantt!D37 -> 46270 | E35: =Gantt!G37 -> Terminé | F35: Gestion des comptes, attribution des tâches, espace dédié à chaque client. | G35: AdminPanel.tsx, ClientSpace.tsx
A36: 5.7 | B36: Conteneurisation Docker, PostgreSQL et intégration continue | C36: =Gantt!C38 -> 46230 | D36: =Gantt!D38 -> 46277 | E36: =Gantt!G38 -> Terminé | F36: Stack PostgreSQL + API + frontend en conteneurs ; CI GitHub Actions (tests, typecheck, build). | G36: docker-compose.yml, .github/workflows/ci.yml
A37: J2 | B37: Plateforme intégrée (agents, RAG, tableau de bord) | C37: =Gantt!C39 -> 46232 | D37: =Gantt!D39 -> 46232 | E37: =Gantt!G39 -> Terminé | F37: Commit regroupant copilote, flotte d'agents, RAG et tableau de bord. | G37: Commit du 29/07
A38: 6 | B38: Lecture automatique des factures (OCR)
A39: 6.1 | B39: Service OCR et rapprochement avec l'ERP | C39: =Gantt!C41 -> 46266 | D39: =Gantt!D41 -> 46277 | E39: =Gantt!G41 -> Terminé | F39: Extraction des factures, facture structurée, enregistrement et rapprochement avec les écritures de l'ERP. | G39: ml_engine/ocr, docs/OCR.md
A40: 6.2 | B40: Affinage de LayoutLMv3 et intégration hybride | C40: =Gantt!C42 -> 46275 | D40: =Gantt!D42 -> 46286 | E40: =Gantt!G42 -> Terminé | F40: Annotation, entraînement sur Colab, fusion modèle + règles : 79,9 % d'exactitude par champ contre 24,4 % pour les règles. | G40: models/layoutlmv3_factures, docs/LAYOUTLMV3.md
A41: J3 | B41: LayoutLMv3 intégré à la chaîne OCR | C41: =Gantt!C43 -> 46286 | D41: =Gantt!D43 -> 46286 | E41: =Gantt!G43 -> Terminé | F41: Derniers commits LayoutLMv3. | G41: Commits des 20-21/09
...
